Traceback (most recent call last):
  File "E:\lxj\公司项目\项目工程\pythonGeneratFile\SQL2menuFile.py", line 64, in query
    cursor.execute(sqdl)
NameError: name 'sqdl' is not defined
Time: 2018-02-08 14:02:30.241938

Traceback (most recent call last):
  File "E:\lxj\公司项目\项目工程\pythonGeneratFile\SQL2menuFile.py", line 201, in main
    for j in range(len(sqlSet)):
TypeError: object of type 'NoneType' has no len()
Time: 2018-02-08 14:02:30.258939

Traceback (most recent call last):
  File "E:\lxj\公司项目\项目工程\pythonGeneratFile\SQL2menuFile.py", line 46, in connDB
    charset = "utf8"
  File "D:\python\lib\site-packages\pymysql\__init__.py", line 90, in Connect
    return Connection(*args, **kwargs)
  File "D:\python\lib\site-packages\pymysql\connections.py", line 699, in __init__
    self.connect()
  File "D:\python\lib\site-packages\pymysql\connections.py", line 936, in connect
    self._request_authentication()
  File "D:\python\lib\site-packages\pymysql\connections.py", line 1156, in _request_authentication
    auth_packet = self._read_packet()
  File "D:\python\lib\site-packages\pymysql\connections.py", line 1018, in _read_packet
    packet.check_error()
  File "D:\python\lib\site-packages\pymysql\connections.py", line 384, in check_error
    err.raise_mysql_exception(self._data)
  File "D:\python\lib\site-packages\pymysql\err.py", line 107, in raise_mysql_exception
    raise errorclass(errno, errval)
pymysql.err.OperationalError: (1045, "Access denied for user 'root'@'localhost' (using password: YES)")
Time: 2018-02-08 14:07:48.036115

Traceback (most recent call last):
  File "E:\lxj\公司项目\项目工程\pythonGeneratFile\SQL2menuFile.py", line 46, in connDB
    charset = "utf8"
  File "D:\python\lib\site-packages\pymysql\__init__.py", line 90, in Connect
    return Connection(*args, **kwargs)
  File "D:\python\lib\site-packages\pymysql\connections.py", line 699, in __init__
    self.connect()
  File "D:\python\lib\site-packages\pymysql\connections.py", line 936, in connect
    self._request_authentication()
  File "D:\python\lib\site-packages\pymysql\connections.py", line 1156, in _request_authentication
    auth_packet = self._read_packet()
  File "D:\python\lib\site-packages\pymysql\connections.py", line 1018, in _read_packet
    packet.check_error()
  File "D:\python\lib\site-packages\pymysql\connections.py", line 384, in check_error
    err.raise_mysql_exception(self._data)
  File "D:\python\lib\site-packages\pymysql\err.py", line 107, in raise_mysql_exception
    raise errorclass(errno, errval)
pymysql.err.OperationalError: (1045, "Access denied for user 'root'@'localhost' (using password: YES)")
Time: 2018-02-08 14:14:03.436586

